Workbook

Sheet N2O
O1: DATA INPUT | S1: DATA CHECK
A2: SOLUBILITY & SATURATION OF N2O IN GF2024 | G2: Campaign | H2: Station_CTD | I2: Station-ID at sea | J2: Stationfor MS | K2: Date | L2: Depth | M2: Comment | N2: Sample ID | O2: Temperature | P2: Salinity | Q2: N2O conc water measured | R2: Temperature | S2: N2O conc atmosphere | T2: Pressure atmosphere | U2: Solubility Constant (F) | V2: Solubility N2O seawater | W2: N2O Saturation
L3: m | O3: °C | Q3: nmol/L | R3: K | S3: ppb | T3: atm | U3: mol/L atm | V3: nmol/L | W3: %
A4: Constantes
G7: Greenfjord 2024 | H7: 1 | L7: 9.81 | O7: 0.392 | P7: 29.1163 | R7: =273.15+O7 -> 273.542 | S7: 336.66 | T7: 1 | U7: =EXP($C$12+($C$13*(100/R7))+($C$14*LN(R7/100))+($C$15*(R7/100)^2)+(P7*($C$16+($C$17*(R7/100))+($C$18*(R7/100)^2)))) -> 0.048484184 | V7: =S7*T7*U7 -> 16.322686
B8: Weiss and Price (1980) | H8: 1 | L8: 19.87 | O8: 0.5155 | P8: 30.441 | R8: =273.15+O8 -> 273.6655 | S8: =S7 -> 336.66 | T8: =T7 -> 1 | U8: =EXP($C$12+($C$13*(100/R8))+($C$14*LN(R8/100))+($C$15*(R8/100)^2)+(P8*($C$16+($C$17*(R8/100))+($C$18*(R8/100)^2)))) -> 0.04785746 | V8: =S8*T8*U8 -> 16.111692
B9: N2O | H9: 1 | L9: 279.94 | O9: 3.9495 | P9: 34.5434 | R9: =273.15+O9 -> 277.0995 | S9: =S8 -> 336.66 | T9: =T8 -> 1 | U9: =EXP($C$12+($C$13*(100/R9))+($C$14*LN(R9/100))+($C$15*(R9/100)^2)+(P9*($C$16+($C$17*(R9/100))+($C$18*(R9/100)^2)))) -> 0.040758982 | V9: =S9*T9*U9 -> 13.721919
B10: F | C10: F | D10: K0 | E10: K0 | H10: 1 | L10: 2.88 | O10: 3.7643 | P10: 22.9 | Q10: 15.226273 | R10: =273.15+O10 -> 276.9143 | S10: =S9 -> 336.66 | T10: =T9 -> 1 | U10: =EXP($C$12+($C$13*(100/R10))+($C$14*LN(R10/100))+($C$15*(R10/100)^2)+(P10*($C$16+($C$17*(R10/100))+($C$18*(R10/100)^2)))) -> 0.043943481 | V10: =S10*T10*U10 -> 14.794012 | W10: =(Q10/V10)*100 -> 102.92187
B11: mol/kg atm | C11: mol/L atm | D11: mol/kg atm | E11: mol/L atm | H11: 1 | L11: 45.17 | O11: 0.9587 | P11: 31.8636 | Q11: 15.40595 | R11: =273.15+O11 -> 274.1087 | S11: =S10 -> 336.66 | T11: =T10 -> 1 | U11: =EXP($C$12+($C$13*(100/R11))+($C$14*LN(R11/100))+($C$15*(R11/100)^2)+(P11*($C$16+($C$17*(R11/100))+($C$18*(R11/100)^2)))) -> 0.046603976 | V11: =S11*T11*U11 -> 15.689694 | W11: =(Q11/V11)*100 -> 98.191521
A12: A1 | B12: -168.2459 | C12: -165.8806 | E12: -62.7062 | H12: 1 | L12: 45.17 | O12: 0.9587 | P12: 31.8636 | Q12: 15.40595 | R12: =273.15+O12 -> 274.1087 | S12: =S11 -> 336.66 | T12: =T11 -> 1 | U12: =EXP($C$12+($C$13*(100/R12))+($C$14*LN(R12/100))+($C$15*(R12/100)^2)+(P12*($C$16+($C$17*(R12/100))+($C$18*(R12/100)^2)))) -> 0.046603976 | V12: =S12*T12*U12 -> 15.689694 | W12: =(Q12/V12)*100 -> 98.191521
A13: A2 | B13: 226.0894 | C13: 222.8743 | E13: 97.3066 | H13: 1 | L13: 6.2 | O13: 0.6024 | P13: 28.1334 | Q13: 14.556584 | R13: =273.15+O13 -> 273.7524 | S13: =S12 -> 336.66 | T13: =T12 -> 1 | U13: =EXP($C$12+($C$13*(100/R13))+($C$14*LN(R13/100))+($C$15*(R13/100)^2)+(P13*($C$16+($C$17*(R13/100))+($C$18*(R13/100)^2)))) -> 0.048353259 | V13: =S13*T13*U13 -> 16.278608 | W13: =(Q13/V13)*100 -> 89.421553
A14: A3 | B14: 93.2817 | C14: 92.0792 | E14: 24.1406 | H14: 1 | L14: 309.6 | O14: 4.0235 | P14: 34.6025 | Q14: 12.751119 | R14: =273.15+O14 -> 277.1735 | S14: =S13 -> 336.66 | T14: =T13 -> 1 | U14: =EXP($C$12+($C$13*(100/R14))+($C$14*LN(R14/100))+($C$15*(R14/100)^2)+(P14*($C$16+($C$17*(R14/100))+($C$18*(R14/100)^2)))) -> 0.040628841 | V14: =S14*T14*U14 -> 13.678106 | W14: =(Q14/V14)*100 -> 93.222842
A15: A4 | B15: sz | C15: -1.48425 | H15: 1 | L15: 85.13 | O15: 0.0905 | P15: 32.5198 | Q15: 14.903735 | R15: =273.15+O15 -> 273.2405 | S15: =S14 -> 336.66 | T15: =T14 -> 1 | U15: =EXP($C$12+($C$13*(100/R15))+($C$14*LN(R15/100))+($C$15*(R15/100)^2)+(P15*($C$16+($C$17*(R15/100))+($C$18*(R15/100)^2)))) -> 0.048091085 | V15: =S15*T15*U15 -> 16.190345 | W15: =(Q15/V15)*100 -> 92.053229
A16: B1 | B16: -0.060361 | C16: -0.056235 | E16: -0.05842 | H16: 2 | L16: 15.13 | O16: 0.355 | P16: 29.8899 | Q16: 15.906762 | R16: =273.15+O16 -> 273.505 | S16: =S15 -> 336.66 | T16: =T15 -> 1 | U16: =EXP($C$12+($C$13*(100/R16))+($C$14*LN(R16/100))+($C$15*(R16/100)^2)+(P16*($C$16+($C$17*(R16/100))+($C$18*(R16/100)^2)))) -> 0.048332314 | V16: =S16*T16*U16 -> 16.271557 | W16: =(Q16/V16)*100 -> 97.758083
A17: B2 | B17: 0.033765 | C17: 0.031619 | E17: 0.033193 | H17: 2 | L17: 1.93 | O17: 2.2101 | P17: 20.6037 | R17: =273.15+O17 -> 275.3601 | S17: =S16 -> 336.66 | T17: =T16 -> 1 | U17: =EXP($C$12+($C$13*(100/R17))+($C$14*LN(R17/100))+($C$15*(R17/100)^2)+(P17*($C$16+($C$17*(R17/100))+($C$18*(R17/100)^2)))) -> 0.047379851 | V17: =S17*T17*U17 -> 15.950901
A18: B3 | B18: -0.0051862 | C18: -0.0048472 | E18: -0.0051313 | H18: 2 | L18: 300.38 | O18: 3.9741 | P18: 34.5762 | Q18: 14.924365 | R18: =273.15+O18 -> 277.1241 | S18: =S17 -> 336.66 | T18: =T17 -> 1 | U18: =EXP($C$12+($C$13*(100/R18))+($C$14*LN(R18/100))+($C$15*(R18/100)^2)+(P18*($C$16+($C$17*(R18/100))+($C$18*(R18/100)^2)))) -> 0.040712531 | V18: =S18*T18*U18 -> 13.706281 | W18: =(Q18/V18)*100 -> 108.88705
H19: 2 | L19: 39.92 | O19: 1.3149 | P19: 31.7768 | R19: =273.15+O19 -> 274.4649 | S19: =S18 -> 336.66 | T19: =T18 -> 1 | U19: =EXP($C$12+($C$13*(100/R19))+($C$14*LN(R19/100))+($C$15*(R19/100)^2)+(P19*($C$16+($C$17*(R19/100))+($C$18*(R19/100)^2)))) -> 0.045962573 | V19: =S19*T19*U19 -> 15.47376
A20: K0 sont les constantes de l'ancien papier qui n'inclue pas l'effet de la vapeur d'eau sur la solubilité | H20: 2 | L20: 5.92 | O20: 0.5908 | P20: 27.1761 | Q20: 16.388681 | R20: =273.15+O20 -> 273.7408 | S20: =S19 -> 336.66 | T20: =T19 -> 1 | U20: =EXP($C$12+($C$13*(100/R20))+($C$14*LN(R20/100))+($C$15*(R20/100)^2)+(P20*($C$16+($C$17*(R20/100))+($C$18*(R20/100)^2)))) -> 0.048654993 | V20: =S20*T20*U20 -> 16.38019 | W20: =(Q20/V20)*100 -> 100.05184
A21: F sont les nouvelles contantes qui considèrent l'effet de la vapeur d'eau sur la solubilité | H21: 2 | L21: 90.07 | O21: 0.0034 | P21: 32.5199 | R21: =273.15+O21 -> 273.1534 | S21: =S20 -> 336.66 | T21: =T20 -> 1 | U21: =EXP($C$12+($C$13*(100/R21))+($C$14*LN(R21/100))+($C$15*(R21/100)^2)+(P21*($C$16+($C$17*(R21/100))+($C$18*(R21/100)^2)))) -> 0.048263094 | V21: =S21*T21*U21 -> 16.248253
A22: Comme nous somme dans un environnement 100% humide sans la présence de phase gazeuse, ce sont les constantes F qui doivent être utilisées | H22: 3 | L22: 9.89 | O22: 0.2225 | P22: 29.1919 | Q22: 16.113663 | R22: =273.15+O22 -> 273.3725 | S22: =S21 -> 336.66 | T22: =T21 -> 1 | U22: =EXP($C$12+($C$13*(100/R22))+($C$14*LN(R22/100))+($C$15*(R22/100)^2)+(P22*($C$16+($C$17*(R22/100))+($C$18*(R22/100)^2)))) -> 0.048800163 | V22: =S22*T22*U22 -> 16.429063 | W22: =(Q22/V22)*100 -> 98.080232
A23: La différence finale sur la saturation est le l'ordre de 3-4%, avec K0 qui sous-estime la saturation par rapport à F | H23: 3 | L23: 175.03 | O23: 1.3925 | P23: 33.5947 | R23: =273.15+O23 -> 274.5425 | S23: =S22 -> 336.66 | T23: =T22 -> 1 | U23: =EXP($C$12+($C$13*(100/R23))+($C$14*LN(R23/100))+($C$15*(R23/100)^2)+(P23*($C$16+($C$17*(R23/100))+($C$18*(R23/100)^2)))) -> 0.045325336 | V23: =S23*T23*U23 -> 15.259227
H24: 3 | L24: 249.97 | O24: 3.5333 | P24: 34.3615 | R24: =273.15+O24 -> 276.6833 | S24: =S23 -> 336.66 | T24: =T23 -> 1 | U24: =EXP($C$12+($C$13*(100/R24))+($C$14*LN(R24/100))+($C$15*(R24/100)^2)+(P24*($C$16+($C$17*(R24/100))+($C$18*(R24/100)^2)))) -> 0.041464899 | V24: =S24*T24*U24 -> 13.959573
H25: 3 | L25: 3.08 | O25: 1.2716 | P25: 23.1983 | Q25: 15.99786 | R25: =273.15+O25 -> 274.4216 | S25: =S24 -> 336.66 | T25: =T24 -> 1 | U25: =EXP($C$12+($C$13*(100/R25))+($C$14*LN(R25/100))+($C$15*(R25/100)^2)+(P25*($C$16+($C$17*(R25/100))+($C$18*(R25/100)^2)))) -> 0.048461627 | V25: =S25*T25*U25 -> 16.315091 | W25: =(Q25/V25)*100 -> 98.055597
H26: 3 | L26: 34.63 | O26: 1.3549 | P26: 31.4891 | Q26: 15.512427 | R26: =273.15+O26 -> 274.5049 | S26: =S25 -> 336.66 | T26: =T25 -> 1 | U26: =EXP($C$12+($C$13*(100/R26))+($C$14*LN(R26/100))+($C$15*(R26/100)^2)+(P26*($C$16+($C$17*(R26/100))+($C$18*(R26/100)^2)))) -> 0.045967454 | V26: =S26*T26*U26 -> 15.475403 | W26: =(Q26/V26)*100 -> 100.23925
H27: 3 | L27: 550.16 | O27: 4.3803 | P27: 34.7229 | R27: =273.15+O27 -> 277.5303 | S27: =S26 -> 336.66 | T27: =T26 -> 1 | U27: =EXP($C$12+($C$13*(100/R27))+($C$14*LN(R27/100))+($C$15*(R27/100)^2)+(P27*($C$16+($C$17*(R27/100))+($C$18*(R27/100)^2)))) -> 0.040047438 | V27: =S27*T27*U27 -> 13.48237
H28: 3 | L28: 85.38 | O28: 0.1583 | P28: 32.4608 | Q28: 16.896568 | R28: =273.15+O28 -> 273.3083 | S28: =S27 -> 336.66 | T28: =T27 -> 1 | U28: =EXP($C$12+($C$13*(100/R28))+($C$14*LN(R28/100))+($C$15*(R28/100)^2)+(P28*($C$16+($C$17*(R28/100))+($C$18*(R28/100)^2)))) -> 0.0479748 | V28: =S28*T28*U28 -> 16.151196 | W28: =(Q28/V28)*100 -> 104.61496
H29: 4 | L29: 2.05 | O29: 4.1076 | P29: 18.4008 | Q29: 14.997564 | R29: =273.15+O29 -> 277.2576 | S29: =S28 -> 336.66 | T29: =T28 -> 1 | U29: =EXP($C$12+($C$13*(100/R29))+($C$14*LN(R29/100))+($C$15*(R29/100)^2)+(P29*($C$16+($C$17*(R29/100))+($C$18*(R29/100)^2)))) -> 0.044509326 | V29: =S29*T29*U29 -> 14.98451 | W29: =(Q29/V29)*100 -> 100.08712
H30: 4 | L30: 20.09 | O30: 0.4808 | P30: 30.3837 | R30: =273.15+O30 -> 273.6308 | S30: =S29 -> 336.66 | T30: =T29 -> 1 | U30: =EXP($C$12+($C$13*(100/R30))+($C$14*LN(R30/100))+($C$15*(R30/100)^2)+(P30*($C$16+($C$17*(R30/100))+($C$18*(R30/100)^2)))) -> 0.047941805 | V30: =S30*T30*U30 -> 16.140088
H31: 4 | L31: 249.58 | O31: 3.5783 | P31: 34.3781 | Q31: 15.665606 | R31: =273.15+O31 -> 276.7283 | S31: =S30 -> 336.66 | T31: =T30 -> 1 | U31: =EXP($C$12+($C$13*(100/R31))+($C$14*LN(R31/100))+($C$15*(R31/100)^2)+(P31*($C$16+($C$17*(R31/100))+($C$18*(R31/100)^2)))) -> 0.041388521 | V31: =S31*T31*U31 -> 13.933859 | W31: =(Q31/V31)*100 -> 112.42834
H32: 4 | L32: 34.38 | O32: 1.1226 | P32: 31.4207 | Q32: 15.756181 | R32: =273.15+O32 -> 274.2726 | S32: =S31 -> 336.66 | T32: =T31 -> 1 | U32: =EXP($C$12+($C$13*(100/R32))+($C$14*LN(R32/100))+($C$15*(R32/100)^2)+(P32*($C$16+($C$17*(R32/100))+($C$18*(R32/100)^2)))) -> 0.046418961 | V32: =S32*T32*U32 -> 15.627407 | W32: =(Q32/V32)*100 -> 100.82402
H33: 4 | L33: 546.44 | O33: 4.4084 | P33: 34.728 | Q33: 14.572579 | R33: =273.15+O33 -> 277.5584 | S33: =S32 -> 336.66 | T33: =T32 -> 1 | U33: =EXP($C$12+($C$13*(100/R33))+($C$14*LN(R33/100))+($C$15*(R33/100)^2)+(P33*($C$16+($C$17*(R33/100))+($C$18*(R33/100)^2)))) -> 0.040003152 | V33: =S33*T33*U33 -> 13.467461 | W33: =(Q33/V33)*100 -> 108.20584
H34: 4 | L34: 5.93 | O34: 0.8806 | P34: 27.4808 | Q34: 15.312603 | R34: =273.15+O34 -> 274.0306 | S34: =S33 -> 336.66 | T34: =T33 -> 1 | U34: =EXP($C$12+($C$13*(100/R34))+($C$14*LN(R34/100))+($C$15*(R34/100)^2)+(P34*($C$16+($C$17*(R34/100))+($C$18*(R34/100)^2)))) -> 0.047994842 | V34: =S34*T34*U34 -> 16.157943 | W34: =(Q34/V34)*100 -> 94.768265
H35: 4 | L35: 70.33 | O35: 0.3222 | P35: 32.3222 | Q35: 16.504613 | R35: =273.15+O35 -> 273.4722 | S35: =S34 -> 336.66 | T35: =T34 -> 1 | U35: =EXP($C$12+($C$13*(100/R35))+($C$14*LN(R35/100))+($C$15*(R35/100)^2)+(P35*($C$16+($C$17*(R35/100))+($C$18*(R35/100)^2)))) -> 0.04769418 | V35: =S35*T35*U35 -> 16.056723 | W35: =(Q35/V35)*100 -> 102.78942
H36: 6 | L36: 99.83 | O36: 0.6848 | P36: 31.5599 | R36: =273.15+O36 -> 273.8348 | S36: =S35 -> 336.66 | T36: =T35 -> 1 | U36: =EXP($C$12+($C$13*(100/R36))+($C$14*LN(R36/100))+($C$15*(R36/100)^2)+(P36*($C$16+($C$17*(R36/100))+($C$18*(R36/100)^2)))) -> 0.04721043 | V36: =S36*T36*U36 -> 15.893863
H37: 6 | L37: 169.72 | O37: -0.0392 | P37: 32.8199 | Q37: 18.286058 | R37: =273.15+O37 -> 273.1108 | S37: =S36 -> 336.66 | T37: =T36 -> 1 | U37: =EXP($C$12+($C$13*(100/R37))+($C$14*LN(R37/100))+($C$15*(R37/100)^2)+(P37*($C$16+($C$17*(R37/100))+($C$18*(R37/100)^2)))) -> 0.048260088 | V37: =S37*T37*U37 -> 16.247241 | W37: =(Q37/V37)*100 -> 112.5487
H38: 6 | L38: 19.54 | O38: 0.7188 | P38: 29.4013 | Q38: 16.299479 | R38: =273.15+O38 -> 273.8688 | S38: =S37 -> 336.66 | T38: =T37 -> 1 | U38: =EXP($C$12+($C$13*(100/R38))+($C$14*LN(R38/100))+($C$15*(R38/100)^2)+(P38*($C$16+($C$17*(R38/100))+($C$18*(R38/100)^2)))) -> 0.047759447 | V38: =S38*T38*U38 -> 16.078696 | W38: =(Q38/V38)*100 -> 101.37314
H39: 6 | L39: 3.16 | O39: 0.8547 | P39: 28.784 | Q39: 16.584541 | R39: =273.15+O39 -> 274.0047 | S39: =S38 -> 336.66 | T39: =T38 -> 1 | U39: =EXP($C$12+($C$13*(100/R39))+($C$14*LN(R39/100))+($C$15*(R39/100)^2)+(P39*($C$16+($C$17*(R39/100))+($C$18*(R39/100)^2)))) -> 0.047671956 | V39: =S39*T39*U39 -> 16.049241 | W39: =(Q39/V39)*100 -> 103.33537
H40: 6 | L40: 40.15 | O40: 0.7897 | P40: 30.7247 | R40: =273.15+O40 -> 273.9397 | S40: =S39 -> 336.66 | T40: =T39 -> 1 | U40: =EXP($C$12+($C$13*(100/R40))+($C$14*LN(R40/100))+($C$15*(R40/100)^2)+(P40*($C$16+($C$17*(R40/100))+($C$18*(R40/100)^2)))) -> 0.047245577 | V40: =S40*T40*U40 -> 15.905696
H41: 6 | L41: 5.81 | O41: 0.8324 | P41: 28.8517 | Q41: 16.407744 | R41: =273.15+O41 -> 273.9824 | S41: =S40 -> 336.66 | T41: =T40 -> 1 | U41: =EXP($C$12+($C$13*(100/R41))+($C$14*LN(R41/100))+($C$15*(R41/100)^2)+(P41*($C$16+($C$17*(R41/100))+($C$18*(R41/100)^2)))) -> 0.04769589 | V41: =S41*T41*U41 -> 16.057298 | W41: =(Q41/V41)*100 -> 102.18247
H42: 7 | L42: 99.99 | O42: 0.6658 | P42: 31.5699 | R42: =273.15+O42 -> 273.8158 | S42: =S41 -> 336.66 | T42: =T41 -> 1 | U42: =EXP($C$12+($C$13*(100/R42))+($C$14*LN(R42/100))+($C$15*(R42/100)^2)+(P42*($C$16+($C$17*(R42/100))+($C$18*(R42/100)^2)))) -> 0.047244079 | V42: =S42*T42*U42 -> 15.905192
...

Sheet CH4
Q1: DATA INPUT | S1: DATA CHECK
A2: SOLUBILITY & SATURATION OF CH4 IN water | G2: Campaign | H2: Station_CTD | I2: Station_ID at sea | J2: Sation for MS | K2: Date | L2: Depth | M2: Comments | N2: Sample ID | O2: Temperature | P2: Salinity | Q2: CH4 conc ice measured | R2: Temperature | S2: CH4 conc atmosphere | T2: fG coefficient | U2: Pressure atmosphere | V2: Solubility Constant (F) | W2: CH4 Saturation
L3: cm | O3: °C | Q3: nmol/L | R3: K | S3: ppb | U3: atm | V3: mol/L atm | W3: %
A4: Constantes
G5: =N2O!G7 -> Greenfjord 2024 | H5: 1 | L5: 9.81 | O5: 0.392 | P5: 29.1163 | R5: =N2O!R7 -> 273.542 | S5: 1986.65 | T5: =S5*10^-9 -> 1.98665e-06 | U5: =N2O!T7 -> 1 | V5: =EXP(LN(T5)+$C$13+($C$14*(100/R5))+($C$15*LN(R5/100))+($C$16*(R5/100))+(P5*($C$17+($C$18*(R5/100))+($C$19*(R5/100)^2)))) -> 4.0524017
H6: 1 | L6: 19.87 | O6: 0.5155 | P6: 30.441 | R6: =N2O!R8 -> 273.6655 | S6: =S5 -> 1986.65 | T6: =T5 -> 1.98665e-06 | U6: =U5 -> 1 | V6: =EXP(LN(T6)+$C$13+($C$14*(100/R6))+($C$15*LN(R6/100))+($C$16*(R6/100))+(P6*($C$17+($C$18*(R6/100))+($C$19*(R6/100)^2)))) -> 3.9989756
H7: 1 | L7: 279.94 | O7: 3.9495 | P7: 34.5434 | R7: =N2O!R9 -> 277.0995 | S7: =S6 -> 1986.65 | T7: =T6 -> 1.98665e-06 | U7: =U6 -> 1 | V7: =EXP(LN(T7)+$C$13+($C$14*(100/R7))+($C$15*LN(R7/100))+($C$16*(R7/100))+(P7*($C$17+($C$18*(R7/100))+($C$19*(R7/100)^2)))) -> 3.5193514
H8: 1 | L8: 2.88 | O8: 3.7643 | P8: 22.9 | Q8: 6.1738481 | R8: =N2O!R10 -> 276.9143 | S8: =S7 -> 1986.65 | T8: =T7 -> 1.98665e-06 | U8: =U7 -> 1 | V8: =EXP(LN(T8)+$C$13+($C$14*(100/R8))+($C$15*LN(R8/100))+($C$16*(R8/100))+(P8*($C$17+($C$18*(R8/100))+($C$19*(R8/100)^2)))) -> 3.8388049 | W8: =(Q8/V8)*100 -> 160.82735
B9: Wiesenburg & Guinasso 1979 | H9: 1 | L9: 45.17 | O9: 0.9587 | P9: 31.8636 | Q9: 5.4979328 | R9: =N2O!R11 -> 274.1087 | S9: =S8 -> 1986.65 | T9: =T8 -> 1.98665e-06 | U9: =U8 -> 1 | V9: =EXP(LN(T9)+$C$13+($C$14*(100/R9))+($C$15*LN(R9/100))+($C$16*(R9/100))+(P9*($C$17+($C$18*(R9/100))+($C$19*(R9/100)^2)))) -> 3.9062747 | W9: =(Q9/V9)*100 -> 140.74619
B10: CH4 | H10: 1 | L10: 45.17 | O10: 0.9587 | P10: 31.8636 | Q10: 5.4979328 | R10: =N2O!R12 -> 274.1087 | S10: =S9 -> 1986.65 | T10: =T9 -> 1.98665e-06 | U10: =U9 -> 1 | V10: =EXP(LN(T10)+$C$13+($C$14*(100/R10))+($C$15*LN(R10/100))+($C$16*(R10/100))+(P10*($C$17+($C$18*(R10/100))+($C$19*(R10/100)^2)))) -> 3.9062747 | W10: =(Q10/V10)*100 -> 140.74619
B11: F | C11: F | H11: 1 | L11: 6.2 | O11: 0.6024 | P11: 28.1334 | Q11: 7.9771456 | R11: =N2O!R13 -> 273.7524 | S11: =S10 -> 1986.65 | T11: =T10 -> 1.98665e-06 | U11: =U10 -> 1 | V11: =EXP(LN(T11)+$C$13+($C$14*(100/R11))+($C$15*LN(R11/100))+($C$16*(R11/100))+(P11*($C$17+($C$18*(R11/100))+($C$19*(R11/100)^2)))) -> 4.0554127 | W11: =(Q11/V11)*100 -> 196.70367
B12: mol/kg atm | C12: mol/L atm | H12: 1 | L12: 309.6 | O12: 4.0235 | P12: 34.6025 | Q12: 5.1351732 | R12: =N2O!R14 -> 277.1735 | S12: =S11 -> 1986.65 | T12: =T11 -> 1.98665e-06 | U12: =U11 -> 1 | V12: =EXP(LN(T12)+$C$13+($C$14*(100/R12))+($C$15*LN(R12/100))+($C$16*(R12/100))+(P12*($C$17+($C$18*(R12/100))+($C$19*(R12/100)^2)))) -> 3.5107611 | W12: =(Q12/V12)*100 -> 146.26951
A13: A1 | C13: -415.2807 | H13: 1 | L13: 85.13 | O13: 0.0905 | P13: 32.5198 | Q13: 5.8095259 | R13: =N2O!R15 -> 273.2405 | S13: =S12 -> 1986.65 | T13: =T12 -> 1.98665e-06 | U13: =U12 -> 1 | V13: =EXP(LN(T13)+$C$13+($C$14*(100/R13))+($C$15*LN(R13/100))+($C$16*(R13/100))+(P13*($C$17+($C$18*(R13/100))+($C$19*(R13/100)^2)))) -> 3.9901605 | W13: =(Q13/V13)*100 -> 145.5963
A14: A2 | C14: 596.8104 | H14: 2 | L14: 15.13 | O14: 0.355 | P14: 29.8899 | Q14: 5.8036443 | R14: =N2O!R16 -> 273.505 | S14: =S13 -> 1986.65 | T14: =T13 -> 1.98665e-06 | U14: =U13 -> 1 | V14: =EXP(LN(T14)+$C$13+($C$14*(100/R14))+($C$15*LN(R14/100))+($C$16*(R14/100))+(P14*($C$17+($C$18*(R14/100))+($C$19*(R14/100)^2)))) -> 4.0343466 | W14: =(Q14/V14)*100 -> 143.85587
A15: A3 | C15: 379.2599 | H15: 2 | L15: 1.93 | O15: 2.2101 | P15: 20.6037 | R15: =N2O!R17 -> 275.3601 | S15: =S14 -> 1986.65 | T15: =T14 -> 1.98665e-06 | U15: =U14 -> 1 | V15: =EXP(LN(T15)+$C$13+($C$14*(100/R15))+($C$15*LN(R15/100))+($C$16*(R15/100))+(P15*($C$17+($C$18*(R15/100))+($C$19*(R15/100)^2)))) -> 4.080147
A16: A4 | C16: -62.0757 | H16: 2 | L16: 300.38 | O16: 3.9741 | P16: 34.5762 | Q16: 5.550365 | R16: =N2O!R18 -> 277.1241 | S16: =S15 -> 1986.65 | T16: =T15 -> 1.98665e-06 | U16: =U15 -> 1 | V16: =EXP(LN(T16)+$C$13+($C$14*(100/R16))+($C$15*LN(R16/100))+($C$16*(R16/100))+(P16*($C$17+($C$18*(R16/100))+($C$19*(R16/100)^2)))) -> 3.5161675 | W16: =(Q16/V16)*100 -> 157.85269
A17: B1 | C17: -0.05916 | H17: 2 | L17: 39.92 | O17: 1.3149 | P17: 31.7768 | R17: =N2O!R19 -> 274.4649 | S17: =S16 -> 1986.65 | T17: =T16 -> 1.98665e-06 | U17: =U16 -> 1 | V17: =EXP(LN(T17)+$C$13+($C$14*(100/R17))+($C$15*LN(R17/100))+($C$16*(R17/100))+(P17*($C$17+($C$18*(R17/100))+($C$19*(R17/100)^2)))) -> 3.8678502
A18: B2 | C18: 0.032174 | H18: 2 | L18: 5.92 | O18: 0.5908 | P18: 27.1761 | Q18: 7.4071939 | R18: =N2O!R20 -> 273.7408 | S18: =S17 -> 1986.65 | T18: =T17 -> 1.98665e-06 | U18: =U17 -> 1 | V18: =EXP(LN(T18)+$C$13+($C$14*(100/R18))+($C$15*LN(R18/100))+($C$16*(R18/100))+(P18*($C$17+($C$18*(R18/100))+($C$19*(R18/100)^2)))) -> 4.0849006 | W18: =(Q18/V18)*100 -> 181.33107
A19: B3 | C19: -0.0048198 | H19: 2 | L19: 90.07 | O19: 0.0034 | P19: 32.5199 | R19: =N2O!R21 -> 273.1534 | S19: =S18 -> 1986.65 | T19: =T18 -> 1.98665e-06 | U19: =U18 -> 1 | V19: =EXP(LN(T19)+$C$13+($C$14*(100/R19))+($C$15*LN(R19/100))+($C$16*(R19/100))+(P19*($C$17+($C$18*(R19/100))+($C$19*(R19/100)^2)))) -> 4.0006851
A20: fG | C20: 1.8953e-06 | H20: 3 | L20: 9.89 | O20: 0.2225 | P20: 29.1919 | Q20: 7.7965131 | R20: =N2O!R22 -> 273.3725 | S20: =S19 -> 1986.65 | T20: =T19 -> 1.98665e-06 | U20: =U19 -> 1 | V20: =EXP(LN(T20)+$C$13+($C$14*(100/R20))+($C$15*LN(R20/100))+($C$16*(R20/100))+(P20*($C$17+($C$18*(R20/100))+($C$19*(R20/100)^2)))) -> 4.071014 | W20: =(Q20/V20)*100 -> 191.51281
H21: 3 | L21: 175.03 | O21: 1.3925 | P21: 33.5947 | R21: =N2O!R23 -> 274.5425 | S21: =S20 -> 1986.65 | T21: =T20 -> 1.98665e-06 | U21: =U20 -> 1 | V21: =EXP(LN(T21)+$C$13+($C$14*(100/R21))+($C$15*LN(R21/100))+($C$16*(R21/100))+(P21*($C$17+($C$18*(R21/100))+($C$19*(R21/100)^2)))) -> 3.8091659
H22: 3 | L22: 249.97 | O22: 3.5333 | P22: 34.3615 | R22: =N2O!R24 -> 276.6833 | S22: =S21 -> 1986.65 | T22: =T21 -> 1.98665e-06 | U22: =U21 -> 1 | V22: =EXP(LN(T22)+$C$13+($C$14*(100/R22))+($C$15*LN(R22/100))+($C$16*(R22/100))+(P22*($C$17+($C$18*(R22/100))+($C$19*(R22/100)^2)))) -> 3.5645467
H23: 3 | L23: 3.08 | O23: 1.2716 | P23: 23.1983 | Q23: 9.2961195 | R23: =N2O!R25 -> 274.4216 | S23: =S22 -> 1986.65 | T23: =T22 -> 1.98665e-06 | U23: =U22 -> 1 | V23: =EXP(LN(T23)+$C$13+($C$14*(100/R23))+($C$15*LN(R23/100))+($C$16*(R23/100))+(P23*($C$17+($C$18*(R23/100))+($C$19*(R23/100)^2)))) -> 4.1182539 | W23: =(Q23/V23)*100 -> 225.72964
H24: 3 | L24: 34.63 | O24: 1.3549 | P24: 31.4891 | Q24: 5.2387018 | R24: =N2O!R26 -> 274.5049 | S24: =S23 -> 1986.65 | T24: =T23 -> 1.98665e-06 | U24: =U23 -> 1 | V24: =EXP(LN(T24)+$C$13+($C$14*(100/R24))+($C$15*LN(R24/100))+($C$16*(R24/100))+(P24*($C$17+($C$18*(R24/100))+($C$19*(R24/100)^2)))) -> 3.8712759 | W24: =(Q24/V24)*100 -> 135.32236
H25: 3 | L25: 550.16 | O25: 4.3803 | P25: 34.7229 | R25: =N2O!R27 -> 277.5303 | S25: =S24 -> 1986.65 | T25: =T24 -> 1.98665e-06 | U25: =U24 -> 1 | V25: =EXP(LN(T25)+$C$13+($C$14*(100/R25))+($C$15*LN(R25/100))+($C$16*(R25/100))+(P25*($C$17+($C$18*(R25/100))+($C$19*(R25/100)^2)))) -> 3.4738215
H26: 3 | L26: 85.38 | O26: 0.1583 | P26: 32.4608 | Q26: 6.6943229 | R26: =N2O!R28 -> 273.3083 | S26: =S25 -> 1986.65 | T26: =T25 -> 1.98665e-06 | U26: =U25 -> 1 | V26: =EXP(LN(T26)+$C$13+($C$14*(100/R26))+($C$15*LN(R26/100))+($C$16*(R26/100))+(P26*($C$17+($C$18*(R26/100))+($C$19*(R26/100)^2)))) -> 3.983699 | W26: =(Q26/V26)*100 -> 168.04289
H27: 4 | L27: 2.05 | O27: 4.1076 | P27: 18.4008 | Q27: 6.3316052 | R27: =N2O!R29 -> 277.2576 | S27: =S26 -> 1986.65 | T27: =T26 -> 1.98665e-06 | U27: =U26 -> 1 | V27: =EXP(LN(T27)+$C$13+($C$14*(100/R27))+($C$15*LN(R27/100))+($C$16*(R27/100))+(P27*($C$17+($C$18*(R27/100))+($C$19*(R27/100)^2)))) -> 3.9237062 | W27: =(Q27/V27)*100 -> 161.36798
H28: 4 | L28: 20.09 | O28: 0.4808 | P28: 30.3837 | R28: =N2O!R30 -> 273.6308 | S28: =S27 -> 1986.65 | T28: =T27 -> 1.98665e-06 | U28: =U27 -> 1 | V28: =EXP(LN(T28)+$C$13+($C$14*(100/R28))+($C$15*LN(R28/100))+($C$16*(R28/100))+(P28*($C$17+($C$18*(R28/100))+($C$19*(R28/100)^2)))) -> 4.0048004
H29: 4 | L29: 249.58 | O29: 3.5783 | P29: 34.3781 | Q29: 5.0883625 | R29: =N2O!R31 -> 276.7283 | S29: =S28 -> 1986.65 | T29: =T28 -> 1.98665e-06 | U29: =U28 -> 1 | V29: =EXP(LN(T29)+$C$13+($C$14*(100/R29))+($C$15*LN(R29/100))+($C$16*(R29/100))+(P29*($C$17+($C$18*(R29/100))+($C$19*(R29/100)^2)))) -> 3.5596885 | W29: =(Q29/V29)*100 -> 142.94404
H30: 4 | L30: 34.38 | O30: 1.1226 | P30: 31.4207 | Q30: 6.0232306 | R30: =N2O!R32 -> 274.2726 | S30: =S29 -> 1986.65 | T30: =T29 -> 1.98665e-06 | U30: =U29 -> 1 | V30: =EXP(LN(T30)+$C$13+($C$14*(100/R30))+($C$15*LN(R30/100))+($C$16*(R30/100))+(P30*($C$17+($C$18*(R30/100))+($C$19*(R30/100)^2)))) -> 3.8997603 | W30: =(Q30/V30)*100 -> 154.4513
H31: 4 | L31: 546.44 | O31: 4.4084 | P31: 34.728 | Q31: 4.7375222 | R31: =N2O!R33 -> 277.5584 | S31: =S30 -> 1986.65 | T31: =T30 -> 1.98665e-06 | U31: =U30 -> 1 | V31: =EXP(LN(T31)+$C$13+($C$14*(100/R31))+($C$15*LN(R31/100))+($C$16*(R31/100))+(P31*($C$17+($C$18*(R31/100))+($C$19*(R31/100)^2)))) -> 3.4710476 | W31: =(Q31/V31)*100 -> 136.48681
H32: 4 | L32: 5.93 | O32: 0.8806 | P32: 27.4808 | Q32: 8.3280678 | R32: =N2O!R34 -> 274.0306 | S32: =S31 -> 1986.65 | T32: =T31 -> 1.98665e-06 | U32: =U31 -> 1 | V32: =EXP(LN(T32)+$C$13+($C$14*(100/R32))+($C$15*LN(R32/100))+($C$16*(R32/100))+(P32*($C$17+($C$18*(R32/100))+($C$19*(R32/100)^2)))) -> 4.0406173 | W32: =(Q32/V32)*100 -> 206.1088
H33: 4 | L33: 70.33 | O33: 0.3222 | P33: 32.3222 | Q33: 5.8547258 | R33: =N2O!R35 -> 273.4722 | S33: =S32 -> 1986.65 | T33: =T32 -> 1.98665e-06 | U33: =U32 -> 1 | V33: =EXP(LN(T33)+$C$13+($C$14*(100/R33))+($C$15*LN(R33/100))+($C$16*(R33/100))+(P33*($C$17+($C$18*(R33/100))+($C$19*(R33/100)^2)))) -> 3.9680547 | W33: =(Q33/V33)*100 -> 147.5465
H34: 6 | L34: 99.83 | O34: 0.6848 | P34: 31.5599 | R34: =N2O!R36 -> 273.8348 | S34: =S33 -> 1986.65 | T34: =T33 -> 1.98665e-06 | U34: =U33 -> 1 | V34: =EXP(LN(T34)+$C$13+($C$14*(100/R34))+($C$15*LN(R34/100))+($C$16*(R34/100))+(P34*($C$17+($C$18*(R34/100))+($C$19*(R34/100)^2)))) -> 3.9468244
H35: 6 | L35: 169.72 | O35: -0.0392 | P35: 32.8199 | Q35: 6.8741498 | R35: =N2O!R37 -> 273.1108 | S35: =S34 -> 1986.65 | T35: =T34 -> 1.98665e-06 | U35: =U34 -> 1 | V35: =EXP(LN(T35)+$C$13+($C$14*(100/R35))+($C$15*LN(R35/100))+($C$16*(R35/100))+(P35*($C$17+($C$18*(R35/100))+($C$19*(R35/100)^2)))) -> 3.997161 | W35: =(Q35/V35)*100 -> 171.9758
H36: 6 | L36: 19.54 | O36: 0.7188 | P36: 29.4013 | Q36: 7.4063601 | R36: =N2O!R38 -> 273.8688 | S36: =S35 -> 1986.65 | T36: =T35 -> 1.98665e-06 | U36: =U35 -> 1 | V36: =EXP(LN(T36)+$C$13+($C$14*(100/R36))+($C$15*LN(R36/100))+($C$16*(R36/100))+(P36*($C$17+($C$18*(R36/100))+($C$19*(R36/100)^2)))) -> 4.0045464 | W36: =(Q36/V36)*100 -> 184.94879
H37: 6 | L37: 3.16 | O37: 0.8547 | P37: 28.784 | Q37: 7.2274973 | R37: =N2O!R39 -> 274.0047 | S37: =S36 -> 1986.65 | T37: =T36 -> 1.98665e-06 | U37: =U36 -> 1 | V37: =EXP(LN(T37)+$C$13+($C$14*(100/R37))+($C$15*LN(R37/100))+($C$16*(R37/100))+(P37*($C$17+($C$18*(R37/100))+($C$19*(R37/100)^2)))) -> 4.0060489 | W37: =(Q37/V37)*100 -> 180.4146
H38: 6 | L38: 40.15 | O38: 0.7897 | P38: 30.7247 | R38: =N2O!R40 -> 273.9397 | S38: =S37 -> 1986.65 | T38: =T37 -> 1.98665e-06 | U38: =U37 -> 1 | V38: =EXP(LN(T38)+$C$13+($C$14*(100/R38))+($C$15*LN(R38/100))+($C$16*(R38/100))+(P38*($C$17+($C$18*(R38/100))+($C$19*(R38/100)^2)))) -> 3.9582094
H39: 6 | L39: 5.81 | O39: 0.8324 | P39: 28.8517 | Q39: 7.3999475 | R39: =N2O!R41 -> 273.9824 | S39: =S38 -> 1986.65 | T39: =T38 -> 1.98665e-06 | U39: =U38 -> 1 | V39: =EXP(LN(T39)+$C$13+($C$14*(100/R39))+($C$15*LN(R39/100))+($C$16*(R39/100))+(P39*($C$17+($C$18*(R39/100))+($C$19*(R39/100)^2)))) -> 4.0067689 | W39: =(Q39/V39)*100 -> 184.68616
H40: 7 | L40: 99.99 | O40: 0.6658 | P40: 31.5699 | R40: =N2O!R42 -> 273.8158 | S40: =S39 -> 1986.65 | T40: =T39 -> 1.98665e-06 | U40: =U39 -> 1 | V40: =EXP(LN(T40)+$C$13+($C$14*(100/R40))+($C$15*LN(R40/100))+($C$16*(R40/100))+(P40*($C$17+($C$18*(R40/100))+($C$19*(R40/100)^2)))) -> 3.9487789
...
